Workbook

Sheet Manpower
A1: Location | B1: Business | C1: Section | D1: Sr_No | E1: Dept_Machine_Name | F1: Designation | G1: Machine_Count | H1: Manpower_Base_Qty | I1: Workload | J1: Formulas | K1: BE_Scientific_Manpower | L1: Operator_Type | M1: Contractors | N1: Company_Associate | O1: BE_Final_Manpower | P1: N_shift | Q1: General_Shift | R1: Shift_A | S1: Shift_B | T1: Shift_C | U1: Reliever | V1: Remarks | W1: SkillType
A2: Anjar | B2: Terry Towel | C2: Terry Towel - Cut & Sew | D2: 1 | E2: Length Cutting | F2: Material movement from Process | H2: 4 | I2: 4 persons / shift | J2: 4*3 | K2: =4*3 -> 12 | L2: Company | M2: 0 | N2: 12 | O2: 12 | P2: 3 | Q2: 0 | R2: 4 | S2: 4 | T2: 4 | U2: 0 | W2: Semi-Skilled
A3: Anjar | B3: Terry Towel | C3: Terry Towel - Cut & Sew | D3: 2 | E3: Length Cutting | F3: Length Cutting Operator | G3: 3 | H3: 2 | I3: 2 operators / machine / shift | J3: LC!J21*2*3 | K3: =LC!J21*2*3 -> 18 | L3: Company | M3: 0 | N3: 18 | O3: 18 | P3: 3 | Q3: 0 | R3: 6 | S3: 6 | T3: 6 | U3: 0 | W3: Skilled
A4: Anjar | B4: Terry Towel | C4: Terry Towel - Cut & Sew | D4: 3 | E4: Length Hemming | F4: Length Hemming Operator | G4: 31 | I4: Auto + Manual machines | J4: ('LH-A'!J18+'LM-M'!J19)*3 | K4: =('LH-A'!J18+'LM-M'!J19)*3 -> 93 | L4: Company | M4: 0 | N4: 93 | O4: 93 | P4: 3 | Q4: 0 | R4: 31 | S4: 31 | T4: 31 | U4: 0 | W4: Skilled
A5: Anjar | B5: Terry Towel | C5: Terry Towel - Cut & Sew | D5: 4 | E5: Length Hemming | F5: Trolley Feeder to LH | H5: 3 | I5: 3 persons / shift | J5: 3*3 | K5: =3*3 -> 9 | L5: Company | M5: 0 | N5: 9 | O5: 9 | P5: 3 | Q5: 0 | R5: 3 | S5: 3 | T5: 3 | U5: 0 | W5: Semi-Skilled
A6: Anjar | B6: Terry Towel | C6: Terry Towel - Cut & Sew | D6: 5 | E6: Length Hemming | F6: Thread Collector (Kitting) | H6: 0 | I6: As per plan | J6: 0 | K6: 0 | L6: Company | M6: 0 | N6: 0 | O6: 0 | P6: 3 | Q6: 0 | R6: 0 | S6: 0 | T6: 0 | U6: 0 | W6: Semi-Skilled
A7: Anjar | B7: Terry Towel | C7: Terry Towel - Cut & Sew | D7: 6 | E7: Length Hemming | F7: L,H,Jobber | H7: 3 | I7: 3 jobbers / shift | J7: 3*3 | K7: =3*3 -> 9 | L7: Company | M7: 0 | N7: 9 | O7: 9 | P7: 3 | Q7: 0 | R7: 3 | S7: 3 | T7: 3 | U7: 0 | W7: Skilled
A8: Anjar | B8: Terry Towel | C8: Terry Towel - Cut & Sew | D8: 7 | E8: Length Hemming | F8: FRC Collecting & Segregation | H8: 1 | I8: 1 person / shift + 1 general | J8: (1+3)+1 | K8: =(1+3)+1 -> 5 | L8: Company | M8: 0 | N8: 4 | O8: 4 | P8: 3 | Q8: 0 | R8: 2 | S8: 1 | T8: 1 | U8: 0 | W8: Semi-Skilled
A9: Anjar | B9: Terry Towel | C9: Terry Towel - Cut & Sew | D9: 8 | E9: Length Hemming | F9: DEO | H9: 1 | I9: 1 DEO / shift | J9: 1*3 | K9: =1*3 -> 3 | L9: Company | M9: 0 | N9: 3 | O9: 3 | P9: 3 | Q9: 0 | R9: 1 | S9: 1 | T9: 1 | U9: 0 | W9: Skilled
A10: Anjar | B10: Terry Towel | C10: Terry Towel - Cut & Sew | D10: 9 | E10: Cross Hemming | F10: Barudan & Schmale | G10: 63 | I10: 1 operator / machine / shift | J10: ACH!J12*3 | K10: =ACH!J12*3 -> 189 | L10: Company | M10: 0 | N10: 189 | O10: 189 | P10: 3 | Q10: 0 | R10: 64 | S10: 64 | T10: 64 | U10: 0 | W10: Skilled
A11: Anjar | B11: Terry Towel | C11: Terry Towel - Cut & Sew | D11: 10 | E11: Cross Hemming | F11: Reliever | H11: 0.13 | I11: 13% of Barudan & Schmale | J11: ROUNDUP(K10*13%,0) | K11: =ROUNDUP(K10*13%,0) -> 25 | L11: Company | M11: 0 | N11: 25 | O11: 25 | P11: 3 | Q11: 0 | R11: 9 | S11: 8 | T11: 8 | U11: 0 | W11: Skilled
A12: Anjar | B12: Terry Towel | C12: Terry Towel - Cut & Sew | D12: 11 | E12: Cross Hemming | F12: Trolley Feeder to CH | H12: 4 | I12: 4 persons / shift | J12: 4*3 | K12: =4*3 -> 12 | L12: Company | M12: 0 | N12: 12 | O12: 12 | P12: 3 | Q12: 0 | R12: 4 | S12: 4 | T12: 4 | U12: 0 | W12: Semi-Skilled
A13: Anjar | B13: Terry Towel | C13: Terry Towel - Cut & Sew | D13: 12 | E13: Cross Hemming | F13: Jobber | H13: 3 | I13: 3 jobbers / shift | J13: 3*3 | K13: =3*3 -> 9 | L13: Company | M13: 0 | N13: 9 | O13: 9 | P13: 3 | Q13: 0 | R13: 3 | S13: 3 | T13: 3 | U13: 0 | W13: Skilled
A14: Anjar | B14: Terry Towel | C14: Terry Towel - Cut & Sew | D14: 13 | E14: Cross Hemming | F14: DEO | H14: 1 | I14: 1 DEO / shift | J14: 1*3 | K14: =1*3 -> 3 | L14: Company | M14: 0 | N14: 3 | O14: 3 | P14: 3 | Q14: 0 | R14: 1 | S14: 1 | T14: 1 | U14: 0 | W14: Skilled
A15: Anjar | B15: Terry Towel | C15: Terry Towel - Cut & Sew | D15: 14 | E15: Cross Hemming | F15: Barudan Drop Collection | H15: 3 | I15: 3 persons / shift + 1 general | J15: (3*3)+1 | K15: =(3*3)+1 -> 10 | L15: Company | M15: 0 | N15: 10 | O15: 10 | P15: 3 | Q15: 0 | R15: 4 | S15: 3 | T15: 3 | U15: 0 | W15: Semi-Skilled
A16: Anjar | B16: Terry Towel | C16: Terry Towel - Cut & Sew | D16: 15 | E16: Cross Hemming Semi-Automatic | F16: CH Semi-Automatic | G16: 11 | H16: 11 | I16: 1 operator / machine / shift | J16: SACH!J11*1*3 | K16: =SACH!J11*1*3 -> 33 | L16: Company | M16: 0 | N16: 33 | O16: 33 | P16: 3 | Q16: 0 | R16: 9 | S16: 9 | T16: 9 | U16: 0 | W16: Skilled
A17: Anjar | B17: Terry Towel | C17: Terry Towel - Cut & Sew | D17: 16 | E17: Cross Hemming Semi-Automatic | F17: Jobber | H17: 1 | I17: 1 jobber / shift | J17: 1*3 | K17: =1*3 -> 3 | L17: Company | M17: 0 | N17: 3 | O17: 3 | P17: 3 | Q17: 0 | R17: 1 | S17: 1 | T17: 1 | U17: 0 | W17: Skilled
A18: Anjar | B18: Terry Towel | C18: Terry Towel - Cut & Sew | D18: 17 | E18: Cross Hemming Semi-Automatic | F18: Material movement Helper | H18: 11 | I18: 1 helper per 2 machines / shift | J18: ROUNDUP(SACH!J11/2,0)*3 | K18: =ROUNDUP(SACH!J11/2,0)*3 -> 18 | L18: Company | M18: 0 | N18: 18 | O18: 18 | P18: 3 | Q18: 0 | R18: 5 | S18: 5 | T18: 5 | U18: 0 | W18: Semi-Skilled
A19: Anjar | B19: Terry Towel | C19: Terry Towel - Cut & Sew | D19: 18 | E19: Cross Hemming Semi-Automatic | F19: CH Alter Operator | H19: 2 | I19: 2 persons / shift | J19: 2*3 | K19: =2*3 -> 6 | L19: Company | M19: 0 | N19: 6 | O19: 6 | P19: 3 | Q19: 0 | R19: 2 | S19: 2 | T19: 2 | U19: 0 | W19: Skilled
A20: Anjar | B20: Terry Towel | C20: Terry Towel - Cut & Sew | D20: 19 | E20: Cross Hemming Semi-Automatic | F20: Packer (11 MMR ratio) | H20: 11 | I20: 11 MMR ratio | J20: SACH!J11*11 | K20: =SACH!J11*11 -> 121 | L20: Company | M20: 0 | N20: 121 | O20: 121 | P20: 3 | Q20: 0 | R20: 33 | S20: 33 | T20: 33 | U20: 0 | W20: Semi-Skilled
A21: Anjar | B21: Terry Towel | C21: Terry Towel - Cut & Sew | D21: 20 | E21: Cross Hemming Semi-Automatic | F21: Carton Packer (5.1 MMR ratio) | H21: 5.1 | I21: 5.1 MMR ratio | J21: SACH!J11*5.1 | K21: =SACH!J11*5.1 -> 56.1 | L21: Company | M21: 0 | N21: 56 | O21: 56 | P21: 3 | Q21: 0 | R21: 16 | S21: 15 | T21: 15 | U21: 0 | W21: Semi-Skilled
A22: Anjar | B22: Terry Towel | C22: Terry Towel - Cut & Sew | D22: 21 | E22: JUKI Alteration - Automatic Section | F22: Cross Rework- Barudan | G22: 35 | H22: 35 | I22: Barudan machines above 8 | J22: (ASCAM!J14-8)*1*3 | K22: =(ASCAM!J14-8)*1*3 -> 81 | L22: Company | M22: 0 | N22: 81 | O22: 81 | P22: 3 | Q22: 0 | R22: 29 | S22: 29 | T22: 29 | U22: 0 | W22: Skilled
A23: Anjar | B23: Terry Towel | C23: Terry Towel - Cut & Sew | D23: 22 | E23: JUKI Alteration - Automatic Section | F23: Cross Rework- Schmale | H23: 8 | I23: 8 Schmale machines | J23: 8*1*3 | K23: =8*1*3 -> 24 | L23: Company | M23: 0 | N23: 24 | O23: 24 | P23: 3 | Q23: 0 | R23: 8 | S23: 8 | T23: 8 | U23: 0 | W23: Skilled
A24: Anjar | B24: Terry Towel | C24: Terry Towel - Cut & Sew | D24: 23 | E24: JUKI Alteration - Automatic Section | F24: Length Rework | G24: 12 | H24: 1 | I24: 1 operator / machine / shift | J24: ASLAM!J14*1*3 | K24: =ASLAM!J14*1*3 -> 36 | L24: Company | M24: 0 | N24: 36 | O24: 36 | P24: 3 | Q24: 0 | R24: 6 | S24: 6 | T24: 6 | U24: 0 | W24: Skilled
A25: Anjar | B25: Terry Towel | C25: Terry Towel - Cut & Sew | D25: 24 | E25: JUKI Alteration - Automatic Section | F25: Length Seam Opening (1.6 MMR) | H25: 1.6 | I25: 1.6 MMR | J25: ROUNDUP(ASLAM!J14*1.6,0) | K25: =ROUNDUP(ASLAM!J14*1.6,0) -> 20 | L25: Company | M25: 0 | N25: 20 | O25: 20 | P25: 3 | Q25: 0 | R25: 4 | S25: 3 | T25: 3 | U25: 0 | W25: Semi-Skilled
A26: Anjar | B26: Terry Towel | C26: Terry Towel - Cut & Sew | D26: 25 | E26: JUKI Alteration - Automatic Section | F26: Mending & PCs recovery of Stitch | H26: 0.4 | I26: 0.4 MMR | J26: ROUND(('LH-A'!J18+'LM-M'!J19)*0.4,0) | K26: =ROUND(('LH-A'!J18+'LM-M'!J19)*0.4,0) -> 12 | L26: Company | M26: 0 | N26: 12 | O26: 12 | P26: 3 | Q26: 0 | R26: 4 | S26: 4 | T26: 4 | U26: 0 | W26: Semi-Skilled
A27: Anjar | B27: Terry Towel | C27: Terry Towel - Cut & Sew | D27: 26 | E27: JUKI Alteration - Automatic Section | F27: Material Feeding to Tailor | G27: 35 | H27: 0.24 | I27: 0.24 MMR | J27: ROUND((ASCAM!J14)*0.24,0) | K27: =ROUND((ASCAM!J14)*0.24,0) -> 8 | L27: Company | M27: 0 | N27: 8 | O27: 8 | P27: 3 | Q27: 0 | R27: 3 | S27: 3 | T27: 3 | U27: 0 | W27: Semi-Skilled
A28: Anjar | B28: Terry Towel | C28: Terry Towel - Cut & Sew | D28: 27 | E28: JUKI Alteration - Automatic Section | F28: Line Jobber | H28: 3 | I28: 3 jobbers / shift | J28: 3*3 | K28: =3*3 -> 9 | L28: Company | M28: 0 | N28: 9 | O28: 9 | P28: 3 | Q28: 0 | R28: 3 | S28: 3 | T28: 3 | U28: 0 | W28: Skilled
A29: Anjar | B29: Terry Towel | C29: Terry Towel - Cut & Sew | D29: 28 | E29: JUKI Alteration - Automatic Section | F29: Label Cutting | H29: 1 | I29: 1 person / shift | J29: 1*3 | K29: =1*3 -> 3 | L29: Company | M29: 0 | N29: 3 | O29: 3 | P29: 3 | Q29: 0 | R29: 1 | S29: 1 | T29: 1 | U29: 0 | W29: Semi-Skilled
A30: Anjar | B30: Terry Towel | C30: Terry Towel - Cut & Sew | D30: 29 | E30: Manual JUKI Section | F30: Jobber | H30: 3 | I30: 3 jobbers / shift | J30: 3*3 | K30: =3*3 -> 9 | L30: Company | M30: 0 | N30: 9 | O30: 9 | P30: 3 | Q30: 0 | R30: 3 | S30: 3 | T30: 3 | U30: 0 | W30: Skilled
A31: Anjar | B31: Terry Towel | C31: Terry Towel - Cut & Sew | D31: 30 | E31: Manual JUKI Section | F31: Label Cutting | H31: 1 | I31: 1 person / shift | J31: 1*3 | K31: =1*3 -> 3 | L31: Company | M31: 0 | N31: 3 | O31: 3 | P31: 3 | Q31: 0 | R31: 1 | S31: 1 | T31: 1 | U31: 0 | W31: Semi-Skilled
A32: Anjar | B32: Terry Towel | C32: Terry Towel - Cut & Sew | D32: 31 | E32: Manual JUKI Section | F32: Towel Cross Cutting | G32: 9 | H32: 1 | I32: Manual LH machines / shift | J32: 'LM-M'!J19*3 | K32: ='LM-M'!J19*3 -> 27 | L32: Company | M32: 0 | N32: 27 | O32: 27 | P32: 3 | Q32: 0 | R32: 9 | S32: 9 | T32: 9 | U32: 0 | W32: Skilled
A33: Anjar | B33: Terry Towel | C33: Terry Towel - Cut & Sew | D33: 32 | E33: Manual JUKI Section | F33: Down Grade - Tailor | H33: 8 | I33: 8 tailors / shift | J33: 8*3 | K33: =8*3 -> 24 | L33: Company | M33: 0 | N33: 24 | O33: 24 | P33: 3 | Q33: 0 | R33: 8 | S33: 8 | T33: 8 | U33: 0 | W33: Skilled
A34: Anjar | B34: Terry Towel | C34: Terry Towel - Cut & Sew | D34: 33 | E34: Manual JUKI Section | F34: Helper - Down Grade | H34: 3 | I34: 3 helpers / shift | J34: 3*3 | K34: =3*3 -> 9 | L34: Company | M34: 0 | N34: 9 | O34: 9 | P34: 3 | Q34: 0 | R34: 3 | S34: 3 | T34: 3 | U34: 0 | W34: Semi-Skilled
A35: Anjar | B35: Terry Towel | C35: Terry Towel - Cut & Sew | D35: 34 | E35: Manual JUKI Section | F35: Tailor - Length Rework | G35: 5 | H35: 1 | I35: 1 tailor / machine / shift | J35: MSLAM!J14*1*3 | K35: =MSLAM!J14*1*3 -> 15 | L35: Company | M35: 0 | N35: 15 | O35: 15 | P35: 3 | Q35: 0 | R35: 2 | S35: 2 | T35: 2 | U35: 0 | W35: Skilled
A36: Anjar | B36: Terry Towel | C36: Terry Towel - Cut & Sew | D36: 35 | E36: Manual JUKI Section | F36: Length Seam Opening (4.31 MMR) | G36: 5 | H36: 4.31 | I36: 4.31 MMR | J36: ROUND(MSLAM!J14*4.31,0) | K36: =ROUND(MSLAM!J14*4.31,0) -> 22 | L36: Company | M36: 0 | N36: 22 | O36: 22 | P36: 3 | Q36: 0 | R36: 3 | S36: 3 | T36: 3 | U36: 0 | W36: Semi-Skilled
A37: Anjar | B37: Terry Towel | C37: Terry Towel - Cut & Sew | D37: 36 | E37: Manual JUKI Section | F37: Tailor - Company Line | G37: 33 | H37: 1 | I37: 1 tailor / machine / shift | J37: MMNO!J16*1*3 | K37: =MMNO!J16*1*3 -> 99 | L37: Company | M37: 0 | N37: 99 | O37: 99 | P37: 3 | Q37: 0 | R37: 33 | S37: 33 | T37: 33 | U37: 0 | W37: Skilled
A38: Anjar | B38: Terry Towel | C38: Terry Towel - Cut & Sew | D38: 37 | E38: Manual JUKI Section | F38: Line Feeding (0.36 MMR) | H38: 0.36 | I38: 0.36 MMR | J38: ROUND(MMNO!J16*0.36,0) | K38: =ROUND(MMNO!J16*0.36,0) -> 12 | L38: Company | M38: 0 | N38: 12 | O38: 12 | P38: 3 | Q38: 0 | R38: 4 | S38: 4 | T38: 4 | U38: 0 | W38: Semi-Skilled
A39: Anjar | B39: Terry Towel | C39: Terry Towel - Cut & Sew | D39: 38 | E39: Manual JUKI Section | F39: DEO | H39: 1 | I39: 1 DEO / shift | J39: 1*3 | K39: =1*3 -> 3 | L39: Company | M39: 0 | N39: 3 | O39: 3 | P39: 3 | Q39: 0 | R39: 1 | S39: 1 | T39: 1 | U39: 0 | W39: Skilled
A40: Anjar | B40: Terry Towel | C40: Terry Towel - Cut & Sew | D40: 39 | E40: Manual JUKI Section | F40: Stain & Mending (0.67 MMR) | H40: 0.67 | I40: 0.67 MMR | J40: ROUND(MMNO!J16*0.67,0) | K40: =ROUND(MMNO!J16*0.67,0) -> 22 | L40: Company | M40: 0 | N40: 22 | O40: 22 | P40: 3 | Q40: 0 | R40: 8 | S40: 8 | T40: 7 | U40: 0 | W40: Semi-Skilled
...

Sheet LC
A1: Month | B1: Machine | C1: Metric | D1: Overall / Common | E1: Bath - 69 x 139 cm | F1: Bath Mat (51 x 76 cm) | G1: Bath Sheet (89 x 164 cm) | H1: Hand (41 x 71 cm) | I1: Wash (33 x 33 cm) | J1: Total / Final
A2: Apr-26 | B2: Length Cutting Machine | C2: Capacity (TPD) | D2: ='WLL Overall'!E11 -> 150284.08
A3: Apr-26 | B3: Length Cutting Machine | C3: Pc Ratio | D3: =D4/D2 -> 4.0236095
A4: Apr-26 | B4: Length Cutting Machine | C4: Total Pcs | D4: ='WLL Overall'!E10 -> 604684.46
A5: Apr-26 | B5: Length Cutting Machine | C5: Ratio % | E5: ='WLL Overall'!E12 -> 0.26153607 | F5: ='WLL Overall'!E13 -> 0.0059467544 | G5: ='WLL Overall'!E14 -> 0.033051916 | H5: ='WLL Overall'!E15 -> 0.33745929 | I5: ='WLL Overall'!E16 -> 0.36200597
A6: Apr-26 | B6: Length Cutting Machine | C6: Production-pcs/day | E6: =$D$4*E5 -> 158146.8 | F6: =$D$4*F5 -> 3595.91 | G6: =$D$4*G5 -> 19985.98 | H6: =$D$4*H5 -> 204056.39 | I6: =$D$4*I5 -> 218899.39
A7: Apr-26 | B7: Length Cutting Machine | C7: Loom Width | E7: 340 | F7: 340 | G7: 340 | H7: 340 | I7: 340
A8: Apr-26 | B8: Length Cutting Machine | C8: Length Per Towel (cm) | E8: =139+11 -> 150 | F8: =76+11 -> 87 | G8: =164+11 -> 175 | H8: =71+11 -> 82 | I8: =33+11 -> 44
A9: Apr-26 | B9: Length Cutting Machine | C9: Width Per Towel (cm) | E9: 74.638182 | F9: 51.466667 | G9: 91.778571 | H9: 45.009877 | I9: 34.379032
A10: Apr-26 | B10: Length Cutting Machine | C10: No of pcs in width | E10: =ROUNDDOWN(E7/E9,0) -> 4 | F10: =ROUNDDOWN(F7/F9,0) -> 6 | G10: =ROUNDDOWN(G7/G9,0) -> 3 | H10: =ROUNDDOWN(H7/H9,0) -> 7 | I10: =ROUNDDOWN(I7/I9,0) -> 9
A11: Apr-26 | B11: Length Cutting Machine | C11: Pcs/mtr | E11: =100/E8 -> 0.66666667 | F11: =100/F8 -> 1.1494253 | G11: =100/G8 -> 0.57142857 | H11: =100/H8 -> 1.2195122 | I11: =100/I8 -> 2.2727273
A12: Apr-26 | B12: Length Cutting Machine | C12: Pcs/lnr mtr | E12: =E11*E10 -> 2.6666667 | F12: =F11*F10 -> 6.8965517 | G12: =G11*G10 -> 1.7142857 | H12: =H11*H10 -> 8.5365854 | I12: =I11*I10 -> 20.454545
A13: Apr-26 | B13: Length Cutting Machine | C13: Speed | E13: 40 | F13: 40 | G13: 40 | H13: 40 | I13: 40
A14: Apr-26 | B14: Length Cutting Machine | C14: Pcs/min | E14: =E13*E12 -> 106.66667 | F14: =F13*F12 -> 275.86207 | G14: =G13*G12 -> 68.571429 | H14: =H13*H12 -> 341.46341 | I14: =I13*I12 -> 818.18182
A15: Apr-26 | B15: Length Cutting Machine | C15: Eff % | E15: 0.75 | F15: 0.75 | G15: 0.75 | H15: 0.75 | I15: 0.75
A16: Apr-26 | B16: Length Cutting Machine | C16: Pcs/min at given eff | E16: =E14*E15 -> 80 | F16: =F14*F15 -> 206.89655 | G16: =G14*G15 -> 51.428571 | H16: =H14*H15 -> 256.09756 | I16: =I14*I15 -> 613.63636
A17: Apr-26 | B17: Length Cutting Machine | C17: Available time | E17: 24 | F17: 24 | G17: 24 | H17: 24 | I17: 24
A18: Apr-26 | B18: Length Cutting Machine | C18: Production/m/c | E18: =E17*60*E16 -> 115200 | F18: =F17*60*F16 -> 297931.03 | G18: =G17*60*G16 -> 74057.143 | H18: =H17*60*H16 -> 368780.49 | I18: =I17*60*I16 -> 883636.36
A19: Apr-26 | B19: Length Cutting Machine | C19: No of machines required | E19: =E6/E18 -> 1.372802 | F19: =F6/F18 -> 0.012069605 | G19: =G6/G18 -> 0.26987241 | H19: =H6/H18 -> 0.55332752 | I19: =I6/I18 -> 0.24772564
A20: Apr-26 | B20: Length Cutting Machine | C20: Total no of machines reqd | J20: =SUM(E19:I19) -> 2.4557972
A21: Apr-26 | B21: Length Cutting Machine | C21: Total No. Of MC | J21: =ROUNDUP(J20,0) -> 3

Sheet LH-A
A1: Month | B1: Machine | C1: Metric | D1: Overall / Common | E1: Bath | F1: Bath - Mat | G1: Bath - Sheet | H1: Hand | I1: Wash | J1: Total / Final
A2: Apr-26 | B2: Length Hemming - Automatic Section Area | C2: Capacity (TPD) | D2: ='WLL - AUTOMATIC'!E3 -> 106860.04
A3: Apr-26 | B3: Length Hemming - Automatic Section Area | C3: Pc Ratio | D3: =D4/D2 -> 4.0334875
A4: Apr-26 | B4: Length Hemming - Automatic Section Area | C4: Total Pcs | D4: ='WLL - AUTOMATIC'!E2 -> 431018.65
A5: Apr-26 | B5: Length Hemming - Automatic Section Area | C5: Ratio % | E5: ='WLL - AUTOMATIC'!E10 -> 0.23656935 | F5: ='WLL - AUTOMATIC'!E11 -> 0.005271023 | G5: ='WLL - AUTOMATIC'!E12 -> 0.027182815 | H5: ='WLL - AUTOMATIC'!E13 -> 0.25361167 | I5: ='WLL - AUTOMATIC'!E14 -> 0.47736514
A6: Apr-26 | B6: Length Hemming - Automatic Section Area | C6: Production-pcs/day | E6: =$D$4*E5 -> 101965.8 | F6: =$D$4*F5 -> 2271.9092 | G6: =$D$4*G5 -> 11716.3 | H6: =$D$4*H5 -> 109311.36 | I6: =$D$4*I5 -> 205753.28
A7: Apr-26 | B7: Length Hemming - Automatic Section Area | C7: Size | E7: =139+11 -> 150 | F7: =76+11 -> 87 | G7: =164+11 -> 175 | H7: =71+11 -> 82 | I7: =33+11 -> 44
A8: Apr-26 | B8: Length Hemming - Automatic Section Area | C8: Qty | E8: =E6 -> 101965.8 | F8: =F6 -> 2271.9092 | G8: =G6 -> 11716.3 | H8: =H6 -> 109311.36 | I8: =I6 -> 205753.28
A9: Apr-26 | B9: Length Hemming - Automatic Section Area | C9: Pcs/mtr | E9: =100/E7 -> 0.66666667 | F9: =100/F7 -> 1.1494253 | G9: =100/G7 -> 0.57142857 | H9: =100/H7 -> 1.2195122 | I9: =100/I7 -> 2.2727273
A10: Apr-26 | B10: Length Hemming - Automatic Section Area | C10: Speed | E10: 16 | F10: 16 | G10: 16 | H10: 16 | I10: 16
A11: Apr-26 | B11: Length Hemming - Automatic Section Area | C11: Pcs/min | E11: =E10*E9 -> 10.666667 | F11: =F10*F9 -> 18.390805 | G11: =G10*G9 -> 9.1428571 | H11: =H10*H9 -> 19.512195 | I11: =I10*I9 -> 36.363636
A12: Apr-26 | B12: Length Hemming - Automatic Section Area | C12: Eff % | E12: 0.75 | F12: 0.75 | G12: 0.75 | H12: 0.75 | I12: 0.75
A13: Apr-26 | B13: Length Hemming - Automatic Section Area | C13: Pcs/min at given eff | E13: =E11*E12 -> 8 | F13: =F11*F12 -> 13.793103 | G13: =G11*G12 -> 6.8571429 | H13: =H11*H12 -> 14.634146 | I13: =I11*I12 -> 27.272727
A14: Apr-26 | B14: Length Hemming - Automatic Section Area | C14: Available time | E14: 22.5 | F14: 22.5 | G14: 22.5 | H14: 22.5 | I14: 22.5
A15: Apr-26 | B15: Length Hemming - Automatic Section Area | C15: Production/m/c | E15: =E14*60*E13 -> 10800 | F15: =F14*60*F13 -> 18620.69 | G15: =G14*60*G13 -> 9257.1429 | H15: =H14*60*H13 -> 19756.098 | I15: =I14*60*I13 -> 36818.182
A16: Apr-26 | B16: Length Hemming - Automatic Section Area | C16: No of machines required | E16: =E8/E15 -> 9.441278 | F16: =F8/F15 -> 0.12200994 | G16: =G8/G15 -> 1.2656497 | H16: =H8/H15 -> 5.5330442 | I16: =I8/I15 -> 5.5883607
A17: Apr-26 | B17: Length Hemming - Automatic Section Area | C17: Total no of machines reqd | J17: =SUM(E16:I16) -> 21.950343
A18: Apr-26 | B18: Length Hemming - Automatic Section Area | C18: Total No. Of MC | J18: =ROUNDUP(J17,0) -> 22

Sheet LM-M
A1: Month | B1: Machine | C1: Metric | D1: Overall / Common | E1: Bath | F1: Bath - Mat | G1: Bath - Sheet | H1: Hand | I1: Wash | J1: Total / Final
A2: Apr-26 | B2: Length Hemming - Manual Section Area | C2: Capacity (TPD) | D2: =('WLL Overall'!E5+'WLL Overall'!E7+'WLL Overall'!E9) -> 43424.038
A3: Apr-26 | B3: Length Hemming - Manual Section Area | C3: Pc Ratio | D3: 4
A4: Apr-26 | B4: Length Hemming - Manual Section Area | C4: Total Pcs | D4: =('WLL Overall'!E4+'WLL Overall'!E6+'WLL Overall'!E8) -> 173665.81
A5: Apr-26 | B5: Length Hemming - Manual Section Area | C5: Ratio % | E5: 0.2158 | F5: 0.005 | G5: 0.0305 | H5: 0.3392 | I5: 0.1224
A6: Apr-26 | B6: Length Hemming - Manual Section Area | C6: Production-pcs/day | E6: =$D$4*E5 -> 37477.082 | F6: =$D$4*F5 -> 868.32906 | G6: =$D$4*G5 -> 5296.8073 | H6: =$D$4*H5 -> 58907.443 | I6: =$D$4*I5 -> 21256.695
A7: Apr-26 | B7: Length Hemming - Manual Section Area | C7: Size | E7: 150 | F7: 87 | G7: 175 | H7: 82 | I7: 44
A8: Apr-26 | B8: Length Hemming - Manual Section Area | C8: Qty | E8: =E6 -> 37477.082 | F8: =F6 -> 868.32906 | G8: =G6 -> 5296.8073 | H8: =H6 -> 58907.443 | I8: =I6 -> 21256.695
A9: Apr-26 | B9: Length Hemming - Manual Section Area | C9: Pcs/mtr | E9: =100/E7 -> 0.66666667 | F9: =100/F7 -> 1.1494253 | G9: =100/G7 -> 0.57142857 | H9: =100/H7 -> 1.2195122 | I9: =100/I7 -> 2.2727273
A10: Apr-26 | B10: Length Hemming - Manual Section Area | C10: Speed | E10: 16 | F10: 16 | G10: 16 | H10: 16 | I10: 16
A11: Apr-26 | B11: Length Hemming - Manual Section Area | C11: Pcs/min | E11: =E10*E9 -> 10.666667 | F11: =F10*F9 -> 18.390805 | G11: =G10*G9 -> 9.1428571 | H11: =H10*H9 -> 19.512195 | I11: =I10*I9 -> 36.363636
A12: Apr-26 | B12: Length Hemming - Manual Section Area | C12: Eff % | E12: 0.75 | F12: 0.75 | G12: 0.75 | H12: 0.75 | I12: 0.75
A13: Apr-26 | B13: Length Hemming - Manual Section Area | C13: Pcs/min at given eff | E13: =E11*E12 -> 8 | F13: =F11*F12 -> 13.793103 | G13: =G11*G12 -> 6.8571429 | H13: =H11*H12 -> 14.634146 | I13: =I11*I12 -> 27.272727
A14: Apr-26 | B14: Length Hemming - Manual Section Area | C14: Available time | E14: 22.5 | F14: 22.5 | G14: 22.5 | H14: 22.5 | I14: 22.5
A15: Apr-26 | B15: Length Hemming - Manual Section Area | C15: Production/m/c | E15: =E14*60*E13 -> 10800 | F15: =F14*60*F13 -> 18620.69 | G15: =G14*60*G13 -> 9257.1429 | H15: =H14*60*H13 -> 19756.098 | I15: =I14*60*I13 -> 36818.182
A16: Apr-26 | B16: Length Hemming - Manual Section Area | C16: No of machines required | E16: =E8/E15 -> 3.4701002 | F16: =F8/F15 -> 0.046632487 | G16: =G8/G15 -> 0.57218597 | H16: =H8/H15 -> 2.9817348 | I16: =I8/I15 -> 0.57734234
A17: Apr-26 | B17: Length Hemming - Manual Section Area | C17: Total no of machines reqd | J17: =SUM(E16:I16) -> 7.6479958
A18: Apr-26 | B18: Length Hemming - Manual Section Area | C18: Samping Machine | J18: 1
A19: Apr-26 | B19: Length Hemming - Manual Section Area | C19: Total No. Of MC | J19: =ROUNDUP(SUM(J17:J18),0) -> 9

Sheet ACH
A1: Month | B1: Machine | C1: Metric | D1: Overall / Common | E1: Bath | F1: Bath - Mat | G1: Bath - Sheet | H1: Hand | I1: Wash | J1: Total / Final
A2: Apr-26 | B2: Auto Cross Hemming | C2: Capacity (TPD) | D2: ='WLL - AUTOMATIC'!E3 -> 106860.04
A3: Apr-26 | B3: Auto Cross Hemming | C3: Pc Ratio | D3: =D4/D2 -> 4.0334875
A4: Apr-26 | B4: Auto Cross Hemming | C4: Total Pcs | D4: ='WLL - AUTOMATIC'!E2 -> 431018.65
A5: Apr-26 | B5: Auto Cross Hemming | C5: Ratio % | E5: ='WLL - AUTOMATIC'!E10 -> 0.23656935 | F5: ='WLL - AUTOMATIC'!E11 -> 0.005271023 | G5: ='WLL - AUTOMATIC'!E12 -> 0.027182815 | H5: ='WLL - AUTOMATIC'!E13 -> 0.25361167 | I5: ='WLL - AUTOMATIC'!E14 -> 0.47736514
A6: Apr-26 | B6: Auto Cross Hemming | C6: Productivity (Pcs/hr) | E6: 307 | F6: 307 | G6: 264 | H6: 360 | I6: 600
A7: Apr-26 | B7: Auto Cross Hemming | C7: Qty | E7: =$D$4*E5 -> 101965.8 | F7: =$D$4*F5 -> 2271.9092 | G7: =$D$4*G5 -> 11716.3 | H7: =$D$4*H5 -> 109311.36 | I7: =$D$4*I5 -> 205753.28
A8: Apr-26 | B8: Auto Cross Hemming | C8: Present Eff | E8: 0.65 | F8: 0.65 | G8: 0.65 | H8: 0.75 | I8: 0.75
A9: Apr-26 | B9: Auto Cross Hemming | C9: Actual Time Available (Hrs) | E9: 24 | F9: 24 | G9: 24 | H9: 24 | I9: 24
A10: Apr-26 | B10: Auto Cross Hemming | C10: No of machines required | E10: =E7/(E6*E8*E9) -> 21.29078 | F10: =F7/(F6*F8*F9) -> 0.47438178 | G10: =G7/(G6*G8*G9) -> 2.844867 | H10: =H7/(H6*H8*H9) -> 16.869037 | I10: =I7/(I6*I8*I9) -> 19.05123
A11: Apr-26 | B11: Auto Cross Hemming | C11: Total no of machines reqd | E11: =ROUNDUP(SUM(E10),0) -> 22 | F11: =ROUNDUP(SUM(F10),0) -> 1 | G11: =ROUNDUP(SUM(G10),0) -> 3 | H11: =ROUNDUP(SUM(H10),0) -> 17 | I11: =ROUNDUP(SUM(I10),0) -> 20
A12: Apr-26 | B12: Auto Cross Hemming | C12: Total No. Of MC | J12: =SUM(E11:I11) -> 63

Sheet ASCAM
A1: Month | B1: Machine | C1: Metric | D1: Overall / Common | E1: Bath | F1: Bath - Mat | G1: Bath - Sheet | H1: Hand | I1: Wash | J1: Total / Final
A2: Apr-26 | B2: Automatic Section Cross Alter Machine | C2: Capacity (TPD) | D2: ='WLL - AUTOMATIC'!E3 -> 106860.04
A3: Apr-26 | B3: Automatic Section Cross Alter Machine | C3: Pc Ratio | D3: =D4/D2 -> 4.0334875
A4: Apr-26 | B4: Automatic Section Cross Alter Machine | C4: Total Pcs | D4: ='WLL - AUTOMATIC'!E2 -> 431018.65
A5: Apr-27 | B5: Automatic Section Cross Alter Machine | E5: ='WLL - AUTOMATIC'!E10 -> 0.23656935 | F5: ='WLL - AUTOMATIC'!E11 -> 0.005271023 | G5: ='WLL - AUTOMATIC'!E12 -> 0.027182815 | H5: ='WLL - AUTOMATIC'!E13 -> 0.25361167 | I5: ='WLL - AUTOMATIC'!E14 -> 0.47736514
A6: Apr-28 | B6: Automatic Section Cross Alter Machine | C6: Qty | E6: =$D$4*E5 -> 101965.8 | F6: =$D$4*F5 -> 2271.9092 | G6: =$D$4*G5 -> 11716.3 | H6: =$D$4*H5 -> 109311.36 | I6: =$D$4*I5 -> 205753.28
A7: Apr-26 | B7: Automatic Section Cross Alter Machine | C7: Alter % | E7: 0.05 | F7: 0.05 | G7: 0.05 | H7: 0.03 | I7: 0.015
A8: Apr-26 | B8: Automatic Section Cross Alter Machine | C8: Qty | E8: =E6*E7 -> 5098.2901 | F8: =F6*F7 -> 113.59546 | G8: =G6*G7 -> 585.81501 | H8: =H6*H7 -> 3279.3408 | I8: =I6*I7 -> 3086.2992
A9: Apr-26 | B9: Automatic Section Cross Alter Machine | C9: SAM/Pcs in Min | E9: 0.93955 | F9: 0.93955 | G9: 0.93955 | H9: 0.8075 | I9: 0.615125
A10: Apr-26 | B10: Automatic Section Cross Alter Machine | C10: Productivity/Shift | E10: =(450/E9) -> 478.95269 | F10: =(450/F9) -> 478.95269 | G10: =(450/G9) -> 478.95269 | H10: =(450/H9) -> 557.27554 | I10: =(450/I9) -> 731.55863
A11: Apr-26 | B11: Automatic Section Cross Alter Machine | C11: Present Eff | E11: 0.65 | F11: 0.65 | G11: 0.65 | H11: 0.65 | I11: 0.65
A12: Apr-26 | B12: Automatic Section Cross Alter Machine | C12: Productivity/Shift @65% | E12: =E10*E11 -> 311.31925 | F12: =F10*F11 -> 311.31925 | G12: =G10*G11 -> 311.31925 | H12: =H10*H11 -> 362.2291 | I12: =I10*I11 -> 475.51311
A13: Apr-26 | B13: Automatic Section Cross Alter Machine | C13: No of machines required | E13: =E8/E12 -> 16.376405 | F13: =F8/F12 -> 0.36488416 | G13: =G8/G12 -> 1.8817179 | H13: =H8/H12 -> 9.053223 | I13: =I8/I12 -> 6.4904608
A14: Apr-26 | B14: Automatic Section Cross Alter Machine | C14: Total No. Of MC | J14: =ROUNDUP(SUM(E13:I13),0) -> 35

Sheet ASLAM
A1: Month | B1: Machine | C1: Metric | D1: Overall / Common | E1: Bath | F1: Bath - Mat | G1: Bath - Sheet | H1: Hand | I1: Wash | J1: Total / Final
A2: Apr-26 | B2: Automatic Section Length Alter Machine | C2: Capacity (TPD) | D2: ='WLL - AUTOMATIC'!E3 -> 106860.04
A3: Apr-26 | B3: Automatic Section Length Alter Machine | C3: Pc Ratio | D3: =D4/D2 -> 4.0334875
A4: Apr-26 | B4: Automatic Section Length Alter Machine | C4: Total Pcs | D4: ='WLL - AUTOMATIC'!E2 -> 431018.65
A5: Apr-26 | B5: Automatic Section Length Alter Machine | C5: Ratio % | E5: ='WLL - AUTOMATIC'!E10 -> 0.23656935 | F5: ='WLL - AUTOMATIC'!E11 -> 0.005271023 | G5: ='WLL - AUTOMATIC'!E12 -> 0.027182815 | H5: ='WLL - AUTOMATIC'!E13 -> 0.25361167 | I5: ='WLL - AUTOMATIC'!E14 -> 0.47736514
A6: Apr-26 | B6: Automatic Section Length Alter Machine | C6: Production-pcs/day | E6: =$D$4*E5 -> 101965.8 | F6: =$D$4*F5 -> 2271.9092 | G6: =$D$4*G5 -> 11716.3 | H6: =$D$4*H5 -> 109311.36 | I6: =$D$4*I5 -> 205753.28
A7: Apr-26 | B7: Automatic Section Length Alter Machine | C7: Alter % | E7: 0.0085 | F7: 0.0085 | G7: 0.0085 | H7: 0.0085 | I7: 0.0085
A8: Apr-26 | B8: Automatic Section Length Alter Machine | C8: Qty | E8: =E6*E7 -> 866.70932 | F8: =F6*F7 -> 19.311228 | G8: =G6*G7 -> 99.588552 | H8: =H6*H7 -> 929.14657 | I8: =I6*I7 -> 1748.9029
A9: Apr-26 | B9: Automatic Section Length Alter Machine | C9: SAM/Pcs in Min | E9: 1.1875 | F9: 1.1875 | G9: 1.1875 | H9: 1.064 | I9: 0.66975
A10: Apr-26 | B10: Automatic Section Length Alter Machine | C10: Productivity/Shift | E10: =(450/E9) -> 378.94737 | F10: =(450/F9) -> 378.94737 | G10: =(450/G9) -> 378.94737 | H10: =(450/H9) -> 422.93233 | I10: =(450/I9) -> 671.8925
A11: Apr-26 | B11: Automatic Section Length Alter Machine | C11: Present Eff | E11: 0.65 | F11: 0.65 | G11: 0.65 | H11: 0.65 | I11: 0.65
A12: Apr-26 | B12: Automatic Section Length Alter Machine | C12: Productivity/Shift @65% | E12: =E10*E11 -> 246.31579 | F12: =F10*F11 -> 246.31579 | G12: =G10*G11 -> 246.31579 | H12: =H10*H11 -> 274.90602 | I12: =I10*I11 -> 436.73012
A13: Apr-26 | B13: Automatic Section Length Alter Machine | C13: No of machines required | E13: =E8/E12 -> 3.5186917 | F13: =F8/F12 -> 0.078400286 | G13: =G8/G12 -> 0.4043125 | H13: =H8/H12 -> 3.3798699 | I13: =I8/I12 -> 4.0045391
A14: Apr-26 | B14: Automatic Section Length Alter Machine | C14: Total No. Of MC | J14: =ROUNDUP(SUM(E13:I13),0) -> 12

Sheet SACH
A1: Month | B1: Machine | C1: Metric | D1: Overall / Common | E1: Bath | F1: Bath - Mat | G1: Bath - Sheet | H1: Hand | I1: Wash | J1: Total / Final
A2: Apr-26 | B2: Semi-Auto Cross Hemming | C2: Capacity (TPD) | D2: ='SEMI-AUTOMATIC'!E3 -> 10000
A3: Apr-26 | B3: Semi-Auto Cross Hemming | C3: Pc Ratio | D3: =D4/D2 -> 4.9862373
A4: Apr-26 | B4: Semi-Auto Cross Hemming | C4: Total Pcs | D4: ='SEMI-AUTOMATIC'!E2 -> 49862.373
A5: Apr-26 | B5: Semi-Auto Cross Hemming | C5: Ratio % | E5: ='SEMI-AUTOMATIC'!E9 -> 0.18075318 | F5: ='SEMI-AUTOMATIC'!E10 -> 0.008182196 | G5: ='SEMI-AUTOMATIC'!E11 -> 0 | H5: ='SEMI-AUTOMATIC'!E12 -> 0.53981022 | I5: ='SEMI-AUTOMATIC'!E13 -> 0.2712544
A6: Apr-26 | B6: Semi-Auto Cross Hemming | C6: Productivity (Pcs/hr) | E6: 214 | F6: 214 | H6: 320 | I6: 374
A7: Apr-26 | B7: Semi-Auto Cross Hemming | C7: Qty | E7: =$D$4*E5 -> 9012.7827 | F7: =$D$4*F5 -> 407.98371 | G7: =$D$4*G5 -> 0 | H7: =$D$4*H5 -> 26916.219 | I7: =$D$4*I5 -> 13525.388
A8: Apr-26 | B8: Semi-Auto Cross Hemming | C8: Present Eff | E8: 0.7 | F8: 0.7 | H8: 0.7 | I8: 0.7
A9: Apr-26 | B9: Semi-Auto Cross Hemming | C9: Actual Time Available (Hrs) | E9: 22.5 | F9: 22.5 | G9: 22.5 | H9: 22.5 | I9: 22.5
A10: Apr-26 | B10: Semi-Auto Cross Hemming | C10: No of machines required | E10: =E7/(E6*E8*E9) -> 2.6740195 | F10: =F7/(F6*F8*F9) -> 0.12104546 | G10: =IFERROR((G7/(G6*G8*G9)),"") | H10: =H7/(H6*H8*H9) -> 5.3405196 | I10: =I7/(I6*I8*I9) -> 2.2961358
A11: Apr-26 | B11: Semi-Auto Cross Hemming | C11: Total No. Of MC | J11: =ROUNDUP(SUM(E10:I10),0) -> 11

Sheet MMNO
A1: Month | B1: Machine | C1: Metric | D1: Overall / Common | E1: Bath | F1: Bath - Mat | G1: Bath - Sheet | H1: Hand | I1: Wash | J1: Total / Final
A2: Apr-26 | B2: Manual Machines - Normal Order | C2: Capacity (TPD) | D2: ='WLL - JUKI - Normal'!E2 -> 15098.827
A3: Apr-26 | B3: Manual Machines - Normal Order | C3: Pc Ratio | D3: 4.88
A4: Apr-26 | B4: Manual Machines - Normal Order | C4: Total Pcs | D4: ='WLL - JUKI - Normal'!E3 -> 73650.131
A5: Apr-26 | B5: Manual Machines - Normal Order | C5: Ratio % | E5: ='WLL - JUKI - Normal'!E10 -> 0.22391047 | F5: ='WLL - JUKI - Normal'!E11 -> 0.010016381 | G5: ='WLL - JUKI - Normal'!E12 -> 0.060668205 | H5: ='WLL - JUKI - Normal'!E13 -> 0.63578573 | I5: ='WLL - JUKI - Normal'!E14 -> 0.069619211
A6: Apr-26 | B6: Manual Machines - Normal Order | C6: Size | E6: 150 | F6: 87 | G6: 175 | H6: 82 | I6: 44
A7: Apr-26 | B7: Manual Machines - Normal Order | C7: Qty | E7: =$D$4*E5 -> 16491.036 | F7: =$D$4*F5 -> 737.70777 | G7: =$D$4*G5 -> 4468.2212 | H7: =$D$4*H5 -> 46825.702 | I7: =$D$4*I5 -> 5127.464
A8: Apr-26 | B8: Manual Machines - Normal Order | C8: Avg SAM Value for 1 Pc (Sec) | E8: 28.8 | F8: 28.8 | G8: 32.4 | H8: 19.8 | I8: 16.2
A9: Apr-26 | B9: Manual Machines - Normal Order | C9: Total Time Req for Total Pcs (Secs) | E9: =E8*E7 -> 474941.82 | F9: =F8*F7 -> 21245.984 | G9: =G8*G7 -> 144770.37 | H9: =H8*H7 -> 927148.9 | I9: =I8*I7 -> 83064.916
A10: Apr-26 | B10: Manual Machines - Normal Order | C10: Juki 1 M/c Available Time @ 22.5 Hrs (In Min) | E10: =22.5*60 -> 1350 | F10: =F9*F8 -> 611884.33 | G10: =22.5*60 -> 1350 | H10: =22.5*60 -> 1350 | I10: =22.5*60 -> 1350
A11: Apr-26 | B11: Manual Machines - Normal Order | C11: Present Eff | E11: 0.7 | F11: 0.7 | G11: 0.7 | H11: 0.7 | I11: 0.7
A12: Apr-26 | B12: Manual Machines - Normal Order | C12: Actual Time Available (In Min) | E12: =E11*E10 -> 945 | F12: =E12 -> 945 | G12: =G11*G10 -> 945 | H12: =H11*H10 -> 945 | I12: =I11*I10 -> 945
A13: Apr-26 | B13: Manual Machines - Normal Order | C13: No of machines required | E13: =E9/(E12*60) -> 8.376399 | F13: =F9/(F12*60) -> 0.37470871 | G13: =G9/(G12*60) -> 2.5532693 | H13: =H9/(H12*60) -> 16.351832 | I13: =I9/(I12*60) -> 1.4649897
A14: Apr-26 | B14: Manual Machines - Normal Order | C14: Total no of machines reqd | J14: =SUM(E13:I13) -> 29.121199
A15: Apr-26 | B15: Manual Machines - Normal Order | C15: Spares machine for Labeling, Rework Etc | J15: =J14*10% -> 2.9121199
A16: Apr-26 | B16: Manual Machines - Normal Order | C16: Total No. Of MC | J16: =ROUNDUP(SUM(J14:J15),0) -> 33

Sheet MMCO
A1: Month | B1: Machine | C1: Metric | D1: Overall / Common | E1: Bath | F1: Bath - Mat | G1: Bath - Sheet | H1: Hand | I1: Wash | J1: Total / Final
A2: Apr-26 | B2: Manual Machines - Critical Order | C2: Capacity (TPD) | D2: ='WLL - JUKI - Critical'!E3 -> 18325
A3: Apr-26 | B3: Manual Machines - Critical Order | C3: Pc Ratio | D3: =D4/D2 -> 2.736879
A4: Apr-26 | B4: Manual Machines - Critical Order | C4: Total Pcs | D4: ='WLL - JUKI - Critical'!E2 -> 50153.308
A5: Apr-26 | B5: Manual Machines - Critical Order | C5: Ratio % | E5: ='WLL - JUKI - Critical'!E10 -> 0.61663257 | F5: ='WLL - JUKI - Critical'!E11 -> 0 | G5: ='WLL - JUKI - Critical'!E12 -> 0.067448881 | H5: ='WLL - JUKI - Critical'!E13 -> 0.088795079 | I5: ='WLL - JUKI - Critical'!E14 -> 0.22712347
A6: Apr-26 | B6: Manual Machines - Critical Order | C6: Qty | E6: =$D$4*E5 -> 30926.163 | F6: =$D$4*F5 -> 0 | G6: =$D$4*G5 -> 3382.7845 | H6: =$D$4*H5 -> 4453.367 | I6: =$D$4*I5 -> 11390.994
A7: Apr-26 | B7: Manual Machines - Critical Order | C7: Avg SAM Value for 1 Pc (Sec) | E7: 33.77 | F7: 30.12 | G7: 41.5 | H7: 27.7 | I7: 26.09
A8: Apr-26 | B8: Manual Machines - Critical Order | C8: Total Time Req for Total Pcs (Secs) | E8: =E7*E6 -> 1044376.5 | F8: =F7*F6 -> 0 | G8: =G7*G6 -> 140385.56 | H8: =H7*H6 -> 123358.27 | I8: =I7*I6 -> 297191.02
A9: Apr-26 | B9: Manual Machines - Critical Order | C9: Juki 1 M/c Available Time @ 22.5 Hrs (In Min) | E9: =22.5*60 -> 1350 | F9: =22.5*60 -> 1350 | G9: =22.5*60 -> 1350 | H9: =22.5*60 -> 1350 | I9: =22.5*60 -> 1350
A10: Apr-26 | B10: Manual Machines - Critical Order | C10: Present Eff | E10: 0.65 | F10: 0.65 | G10: 0.65 | H10: 0.65 | I10: 0.65
A11: Apr-26 | B11: Manual Machines - Critical Order | C11: Actual Time Available (In Min) | E11: =E10*E9 -> 877.5 | F11: =F10*F9 -> 877.5 | G11: =G10*G9 -> 877.5 | H11: =H10*H9 -> 877.5 | I11: =I10*I9 -> 877.5
A12: Apr-26 | B12: Manual Machines - Critical Order | C12: No of machines required | E12: =E8/(E11*60) -> 19.836211 | F12: =F8/(F11*60) -> 0 | G12: =G8/(G11*60) -> 2.6663924 | H12: =H8/(H11*60) -> 2.342987 | I12: =I8/(I11*60) -> 5.6446538
A13: Apr-26 | B13: Manual Machines - Critical Order | C13: Total no of machines reqd | J13: =SUM(E12:I12) -> 30.490245
A14: Apr-26 | B14: Manual Machines - Critical Order | C14: Spares machine for Labeling, Rework Etc | J14: =J13*10% -> 3.0490245
A15: Apr-26 | B15: Manual Machines - Critical Order | C15: Total No. Of MC | J15: =ROUNDUP(SUM(J13:J14),0) -> 34

Sheet MSLAM
A1: Month | B1: Machine | C1: Metric | D1: Overall / Common | E1: Bath | F1: Bath - Mat | G1: Bath - Sheet | H1: Hand | I1: Wash | J1: Total / Final
A2: Apr-26 | B2: Manual Section Length Alter Machine | C2: Capacity (TPD) | D2: =('WLL Overall'!E5+'WLL Overall'!E7+'WLL Overall'!E9) -> 43424.038
A3: Apr-26 | B3: Manual Section Length Alter Machine | C3: Pc Ratio | D3: 4
A4: Apr-26 | B4: Manual Section Length Alter Machine | C4: Total Pcs | D4: =('WLL Overall'!E4+'WLL Overall'!E6+'WLL Overall'!E8) -> 173665.81
A5: Apr-26 | B5: Manual Section Length Alter Machine | C5: Ratio % | E5: 0.2158 | F5: 0.005 | G5: 0.0305 | H5: 0.3392 | I5: 0.1224
A6: Apr-26 | B6: Manual Section Length Alter Machine | C6: Production-pcs/day | E6: =$D$4*E5 -> 37477.082 | F6: =$D$4*F5 -> 868.32906 | G6: =$D$4*G5 -> 5296.8073 | H6: =$D$4*H5 -> 58907.443 | I6: =$D$4*I5 -> 21256.695
A7: Apr-26 | B7: Manual Section Length Alter Machine | C7: Alter % | E7: 0.01 | F7: 0.01 | G7: 0.01 | H7: 0.01 | I7: 0.01
A8: Apr-26 | B8: Manual Section Length Alter Machine | C8: Qty | E8: =E6*E7 -> 374.77082 | F8: =F6*F7 -> 8.6832906 | G8: =G6*G7 -> 52.968073 | H8: =H6*H7 -> 589.07443 | I8: =I6*I7 -> 212.56695
A9: Apr-26 | B9: Manual Section Length Alter Machine | C9: SAM/Pcs in Min | E9: 1.1875 | F9: 1.1875 | G9: 1.1875 | H9: 1.064 | I9: 0.66975
A10: Apr-26 | B10: Manual Section Length Alter Machine | C10: Productivity/Shift | E10: =(450/E9) -> 378.94737 | F10: =(450/F9) -> 378.94737 | G10: =(450/G9) -> 378.94737 | H10: =(450/H9) -> 422.93233 | I10: =(450/I9) -> 671.8925
A11: Apr-26 | B11: Manual Section Length Alter Machine | C11: Present Eff | E11: 0.65 | F11: 0.65 | G11: 0.65 | H11: 0.65 | I11: 0.65
A12: Apr-26 | B12: Manual Section Length Alter Machine | C12: Productivity/Shift @65% | E12: =E10*E11 -> 246.31579 | F12: =F10*F11 -> 246.31579 | G12: =G10*G11 -> 246.31579 | H12: =H10*H11 -> 274.90602 | I12: =I10*I11 -> 436.73012
A13: Apr-26 | B13: Manual Section Length Alter Machine | C13: No of machines required | E13: =E8/E12 -> 1.5215055 | F13: =F8/F12 -> 0.035252675 | G13: =G8/G12 -> 0.21504132 | H13: =H8/H12 -> 2.1428212 | I13: =I8/I12 -> 0.48672382
A14: Apr-26 | B14: Manual Section Length Alter Machine | C14: Total No. Of MC | J14: =ROUNDUP(SUM(E13:I13),0) -> 5

Sheet WLL Overall
A1: Month | B1: Section | C1: Metric | D1: Category | E1: Value | F1: Formula
A2: Apr-26 | B2: IE Production/Day | C2: April (Pcs) | D2: Automatic | E2: 431018.65 | F2: input
A3: Apr-26 | B3: IE Production/Day | C3: April (Kgs) | D3: Automatic | E3: 106860.04 | F3: input
A4: Apr-26 | B4: IE Production/Day | C4: April (Pcs) | D4: SEMI-AUTOMATIC | E4: 49862.373 | F4: input
A5: Apr-26 | B5: IE Production/Day | C5: April (Kgs) | D5: SEMI-AUTOMATIC | E5: 10000 | F5: input
A6: Apr-26 | B6: IE Production/Day | C6: April (Pcs) | D6: WLL - JUKI - Critical | E6: 50153.308 | F6: input
A7: Apr-26 | B7: IE Production/Day | C7: April (Kgs) | D7: WLL - JUKI - Critical | E7: 18325.211 | F7: input
A8: Apr-26 | B8: IE Production/Day | C8: April (Pcs) | D8: WLL - JUKI - Normal | E8: 73650.131 | F8: input
A9: Apr-26 | B9: IE Production/Day | C9: April (Kgs) | D9: WLL - JUKI - Normal | E9: 15098.827 | F9: input
A10: Apr-26 | B10: IE Production/Day | C10: April (Pcs) | D10: Grand Total | E10: =SUM(E2,E4,E6,E8) -> 604684.46 | F10: SUM(E2,E4,E6,E8)
A11: Apr-26 | B11: IE Production/Day | C11: April (Kgs) | D11: Grand Total | E11: =SUM(E3,E5,E7,E9) -> 150284.08 | F11: SUM(E3,E5,E7,E9)
A12: Apr-26 | B12: Size Ratio | C12: Ratio | D12: Bath | E12: 0.26153607 | F12: input
A13: Apr-26 | B13: Size Ratio | C13: Ratio | D13: Bath Mat | E13: 0.0059467544 | F13: input
A14: Apr-26 | B14: Size Ratio | C14: Ratio | D14: Bath Sheet | E14: 0.033051916 | F14: input
A15: Apr-26 | B15: Size Ratio | C15: Ratio | D15: Hand | E15: 0.33745929 | F15: input
A16: Apr-26 | B16: Size Ratio | C16: Ratio | D16: Wash | E16: 0.36200597 | F16: input
A17: Apr-26 | B17: Size Ratio | C17: Ratio | D17: Grand Total | E17: =SUM(E12:E16) -> 1 | F17: SUM(E12:E16)
A18: Apr-26 | B18: WLL Overall | C18: April (Pcs) | D18: Bath | E18: =E10*E12 -> 158146.8 | F18: E10*E12
A19: Apr-26 | B19: WLL Overall | C19: April (Pcs) | D19: Bath Mat | E19: =E10*E13 -> 3595.91 | F19: E10*E13
A20: Apr-26 | B20: WLL Overall | C20: April (Pcs) | D20: Bath Sheet | E20: =E10*E14 -> 19985.98 | F20: E10*E14
A21: Apr-26 | B21: WLL Overall | C21: April (Pcs) | D21: Hand | E21: =E10*E15 -> 204056.39 | F21: E10*E15
A22: Apr-26 | B22: WLL Overall | C22: April (Pcs) | D22: Wash | E22: =E10*E16 -> 218899.39 | F22: E10*E16
A23: Apr-26 | B23: WLL Overall | C23: April (Pcs) | D23: Grand Total | E23: =E10*E17 -> 604684.46 | F23: E10*E17
A24: Apr-26 | B24: PC Ratio | C24: Pc Ratio | D24: AUTOMATIC | E24: =E2/E3 -> 4.0334875 | F24: E2/E3
A25: Apr-26 | B25: PC Ratio | C25: Pc Ratio | D25: SEMI-AUTOMATIC | E25: =E4/E5 -> 4.9862373 | F25: E4/E5
A26: Apr-26 | B26: PC Ratio | C26: Pc Ratio | D26: WLL - JUKI - Critical | E26: =E6/E7 -> 2.7368476 | F26: E6/E7
A27: Apr-26 | B27: PC Ratio | C27: Pc Ratio | D27: WLL - JUKI - Normal | E27: =E8/E9 -> 4.877871 | F27: E8/E9
A28: Apr-26 | B28: PC Ratio | C28: Pc Ratio | D28: Grand Total | E28: =E10/E11 -> 4.0236095 | F28: E10/E11

Sheet WLL - AUTOMATIC
A1: Month | B1: Section | C1: Metric | D1: Category | E1: Value | F1: Formula
A2: Apr-26 | B2: WLL - AUTOMATIC | C2: April (Pcs) | D2: Automatic | E2: 431018.65 | F2: Input
A3: Apr-27 | B3: WLL - AUTOMATIC | C3: April (Kgs) | D3: Automatic | E3: 106860.04 | F3: Input
A4: Apr-26 | B4: WLL - AUTOMATIC | C4: April (Pcs) | D4: Bath | E4: =$E$2*E10 -> 101965.8 | F4: Automatic * Ratio
A5: Apr-26 | B5: WLL - AUTOMATIC | C5: April (Pcs) | D5: Mat | E5: =$E$2*E11 -> 2271.9092 | F5: Automatic * Ratio
A6: Apr-26 | B6: WLL - AUTOMATIC | C6: April (Pcs) | D6: Bath Sheet | E6: =$E$2*E12 -> 11716.3 | F6: Automatic * Ratio
A7: Apr-26 | B7: WLL - AUTOMATIC | C7: April (Pcs) | D7: Hand | E7: =$E$2*E13 -> 109311.36 | F7: Automatic * Ratio
A8: Apr-26 | B8: WLL - AUTOMATIC | C8: April (Pcs) | D8: Wash | E8: =$E$2*E14 -> 205753.28 | F8: Automatic * Ratio
A9: Apr-26 | B9: WLL - AUTOMATIC | C9: April (Pcs) | D9: Grand Total | E9: =SUM(E4:E8) -> 431018.65 | F9: Sum
A10: Apr-26 | B10: WLL - AUTOMATIC | C10: Ratio | D10: Bath | E10: 0.23656935 | F10: Input
A11: Apr-26 | B11: WLL - AUTOMATIC | C11: Ratio | D11: Mat | E11: 0.005271023 | F11: Input
A12: Apr-26 | B12: WLL - AUTOMATIC | C12: Ratio | D12: Bath Sheet | E12: 0.027182815 | F12: Input
A13: Apr-26 | B13: WLL - AUTOMATIC | C13: Ratio | D13: Hand | E13: 0.25361167 | F13: Input
A14: Apr-26 | B14: WLL - AUTOMATIC | C14: Ratio | D14: Wash | E14: 0.47736514 | F14: Input
A15: Apr-26 | B15: WLL - AUTOMATIC | C15: Ratio | D15: Grand Total | E15: 1 | F15: Check

Sheet WLL - JUKI Manual Order
A1: Month | B1: Section | C1: Metric | D1: Category | E1: Value | F1: Formula
A2: Apr-26 | B2: WLL - JUKI Manual Order | C2: April (Pcs) | D2: WLL - JUKI - Critical | E2: 50153.308 | F2: Input
A3: Apr-26 | B3: WLL - JUKI Manual Order | C3: April (Pcs) | D3: WLL - JUKI - Normal | E3: 73650.131 | F3: Input
A4: Apr-26 | B4: WLL - JUKI Manual Order | C4: April (Pcs) | D4: Grand Total | E4: 123803.44 | F4: Critical + Normal
A5: Apr-26 | B5: WLL - JUKI Manual Order | C5: Manual Order Day in Pcs | D5: Bath | E5: =$E$4*E11 -> 37477.401 | F5: Grand Total * Ratio
A6: Apr-26 | B6: WLL - JUKI Manual Order | C6: Manual Order Day in Pcs | D6: Bath Mat | E6: =$E$4*E12 -> 874.21669 | F6: Grand Total * Ratio
A7: Apr-26 | B7: WLL - JUKI Manual Order | C7: Manual Order Day in Pcs | D7: Bath Sheet | E7: =$E$4*E13 -> 5290.4426 | F7: Grand Total * Ratio
A8: Apr-26 | B8: WLL - JUKI Manual Order | C8: Manual Order Day in Pcs | D8: Hand | E8: =$E$4*E14 -> 58900.754 | F8: Grand Total * Ratio
A9: Apr-26 | B9: WLL - JUKI Manual Order | C9: Manual Order Day in Pcs | D9: Wash | E9: =$E$4*E15 -> 21260.624 | F9: Grand Total * Ratio
A10: Apr-26 | B10: WLL - JUKI Manual Order | C10: Manual Order Day in Pcs | D10: Grand Total | E10: 123803.44 | F10: Sum
A11: Apr-26 | B11: WLL - JUKI Manual Order | C11: Ratio | D11: Bath | E11: 0.30271697 | F11: Input
A12: Apr-26 | B12: WLL - JUKI Manual Order | C12: Ratio | D12: Bath Mat | E12: 0.007061328 | F12: Input
A13: Apr-26 | B13: WLL - JUKI Manual Order | C13: Ratio | D13: Bath Sheet | E13: 0.042732598 | F13: Input
A14: Apr-26 | B14: WLL - JUKI Manual Order | C14: Ratio | D14: Hand | E14: 0.47576024 | F14: Input
A15: Apr-26 | B15: WLL - JUKI Manual Order | C15: Ratio | D15: Wash | E15: 0.17172887 | F15: Input
A16: Apr-26 | B16: WLL - JUKI Manual Order | C16: Ratio | D16: Grand Total | E16: 1 | F16: Check

Sheet SEMI-AUTOMATIC
A1: Month | B1: Section | C1: Metric | D1: Category | E1: Value | F1: Formula
A2: Apr-26 | B2: SEMI-AUTOMATIC | C2: April (Pcs) | D2: SEMI-AUTOMATIC | E2: 49862.373 | F2: Input
A3: Apr-27 | B3: SEMI-AUTOMATIC | C3: April (Kgs) | D3: SEMI-AUTOMATIC | E3: 10000 | F3: Input
A4: Apr-26 | B4: SEMI-AUTOMATIC | C4: Semi-Automatic day in Pcs | D4: Bath | E4: =$E$2*E9 -> 9012.7827 | F4: Grand Total * Ratio
A5: Apr-26 | B5: SEMI-AUTOMATIC | C5: Semi-Automatic day in Pcs | D5: Bath Mat | E5: =$E$2*E10 -> 407.98371 | F5: Grand Total * Ratio
A6: Apr-26 | B6: SEMI-AUTOMATIC | C6: Semi-Automatic day in Pcs | D6: Hand | E6: =$E$2*E12 -> 26916.219 | F6: Grand Total * Ratio
A7: Apr-26 | B7: SEMI-AUTOMATIC | C7: Semi-Automatic day in Pcs | D7: Wash | E7: =$E$2*E13 -> 13525.388 | F7: Grand Total * Ratio
A8: Apr-26 | B8: SEMI-AUTOMATIC | C8: Semi-Automatic day in Pcs | D8: Grand Total | E8: =SUM(E4:E7) -> 49862.373 | F8: Sum
A9: Apr-26 | B9: SEMI-AUTOMATIC | C9: Ratio | D9: Bath | E9: 0.18075318 | F9: Input
A10: Apr-26 | B10: SEMI-AUTOMATIC | C10: Ratio | D10: Bath Mat | E10: 0.008182196 | F10: Input
A11: Apr-27 | B11: SEMI-AUTOMATIC | C11: Ratio | D11: Bath - Sheet | E11: 0 | F11: Input
A12: Apr-26 | B12: SEMI-AUTOMATIC | C12: Ratio | D12: Hand | E12: 0.53981022 | F12: Input
A13: Apr-26 | B13: SEMI-AUTOMATIC | C13: Ratio | D13: Wash | E13: 0.2712544 | F13: Input
A14: Apr-26 | B14: SEMI-AUTOMATIC | C14: Ratio | D14: Grand Total | E14: 1 | F14: Check

Sheet WLL - JUKI - Normal
A1: Month | B1: Section | C1: Metric | D1: Category | E1: Value | F1: Formula
A2: Apr-26 | B2: WLL - JUKI - Normal | C2: April (Kgs) | D2: WLL - JUKI - Normal | E2: 15098.827 | F2: Input
A3: Apr-27 | B3: WLL - JUKI - Normal | C3: April (Pcs) | D3: WLL - JUKI - Normal | E3: 73650.131 | F3: Input
A4: Apr-26 | B4: WLL - JUKI - Normal | C4: Manual Normal JUKI Day in Pcs | D4: Bath | E4: =$E$3*E10 -> 16491.036 | F4: Grand Total * Ratio
A5: Apr-26 | B5: WLL - JUKI - Normal | C5: Manual Normal JUKI Day in Pcs | D5: Bath Mat | E5: =$E$3*E11 -> 737.70777 | F5: Grand Total * Ratio
A6: Apr-26 | B6: WLL - JUKI - Normal | C6: Manual Normal JUKI Day in Pcs | D6: Bath Sheet | E6: =$E$3*E12 -> 4468.2212 | F6: Grand Total * Ratio
A7: Apr-26 | B7: WLL - JUKI - Normal | C7: Manual Normal JUKI Day in Pcs | D7: Hand | E7: =$E$3*E13 -> 46825.702 | F7: Grand Total * Ratio
A8: Apr-26 | B8: WLL - JUKI - Normal | C8: Manual Normal JUKI Day in Pcs | D8: Wash | E8: =$E$3*E14 -> 5127.464 | F8: Grand Total * Ratio
A9: Apr-26 | B9: WLL - JUKI - Normal | C9: Manual Normal JUKI Day in Pcs | D9: Grand Total | E9: =SUM(E4:E8) -> 73650.131 | F9: Sum
A10: Apr-26 | B10: WLL - JUKI - Normal | C10: Ratio | D10: Bath | E10: 0.22391047 | F10: Input
A11: Apr-26 | B11: WLL - JUKI - Normal | C11: Ratio | D11: Bath Mat | E11: 0.010016381 | F11: Input
A12: Apr-26 | B12: WLL - JUKI - Normal | C12: Ratio | D12: Bath Sheet | E12: 0.060668205 | F12: Input
A13: Apr-26 | B13: WLL - JUKI - Normal | C13: Ratio | D13: Hand | E13: 0.63578573 | F13: Input
A14: Apr-26 | B14: WLL - JUKI - Normal | C14: Ratio | D14: Wash | E14: 0.069619211 | F14: Input
A15: Apr-26 | B15: WLL - JUKI - Normal | C15: Ratio | D15: Grand Total | E15: 1 | F15: Check

Sheet WLL - JUKI - Critical
A1: Month | B1: Section | C1: Metric | D1: Category | E1: Value | F1: Formula
A2: Apr-26 | B2: WLL - JUKI - Critical | C2: April (Pcs) | D2: WLL - JUKI - Critical | E2: 50153.308 | F2: Input
A3: Apr-27 | B3: WLL - JUKI - Critical | C3: April (Kgs) | D3: WLL - JUKI - Critical | E3: 18325 | F3: Input
A4: Apr-26 | B4: WLL - JUKI - Critical | C4: Manual Critical Day in Pcs | D4: Bath | E4: =$E$2*E10 -> 30926.163 | F4: Grand Total * Ratio
A5: Apr-26 | B5: WLL - JUKI - Critical | C5: Manual Critical Day in Pcs | D5: Bath Mat | E5: =$E$2*E11 -> 0 | F5: Grand Total * Ratio
A6: Apr-26 | B6: WLL - JUKI - Critical | C6: Manual Critical Day in Pcs | D6: Bath Sheet | E6: =$E$2*E12 -> 3382.7845 | F6: Grand Total * Ratio
A7: Apr-26 | B7: WLL - JUKI - Critical | C7: Manual Critical Day in Pcs | D7: Hand | E7: =$E$2*E13 -> 4453.367 | F7: Grand Total * Ratio
A8: Apr-26 | B8: WLL - JUKI - Critical | C8: Manual Critical Day in Pcs | D8: Wash | E8: =$E$2*E14 -> 11390.994 | F8: Grand Total * Ratio
A9: Apr-26 | B9: WLL - JUKI - Critical | C9: Manual Critical Day in Pcs | D9: Grand Total | E9: =SUM(E4:E8) -> 50153.308 | F9: Sum
A10: Apr-26 | B10: WLL - JUKI - Critical | C10: Ratio | D10: Bath | E10: 0.61663257 | F10: Input
A11: Apr-26 | B11: WLL - JUKI - Critical | C11: Ratio | D11: Bath Mat | E11: 0 | F11: Input
A12: Apr-26 | B12: WLL - JUKI - Critical | C12: Ratio | D12: Bath Sheet | E12: 0.067448881 | F12: Input
A13: Apr-26 | B13: WLL - JUKI - Critical | C13: Ratio | D13: Hand | E13: 0.088795079 | F13: Input
A14: Apr-26 | B14: WLL - JUKI - Critical | C14: Ratio | D14: Wash | E14: 0.22712347 | F14: Input
A15: Apr-26 | B15: WLL - JUKI - Critical | C15: Ratio | D15: Grand Total | E15: 1 | F15: Check
